<?xml version="1.0" ?>
<!-- =================================================================================== -->
<!-- |    This document was autogenerated by xacro from /smart_grasping_sandbox/src/smart_grasping_sandbox/fh_desc/robots/right_H1_ur5.urdf | -->
<!-- |    EDITING THIS FILE BY HAND IS NOT RECOMMENDED                                 | -->
<!-- =================================================================================== -->
<robot name="smart_grasping_sandbox" xmlns:xacro="http://ros.org/wiki/xacro">
  <!--
  Author: Kelsey Hawkins
  Contributers: Jimmy Da Silva, Ajit Krisshna N L, Muhammad Asif Rana
-->
  <!-- Inertia parameters -->
  <!-- This mass might be incorrect -->
  <!-- These parameters are borrowed from the urcontrol.conf file
       but are not verified for the correct permutation.
       The permutation was guessed by looking at the UR5 parameters.
       Serious use of these parameters needs further inspection. -->
  <!-- Kinematic model -->
  <!-- Properties from urcontrol.conf -->
  <!-- Arbitrary offsets for shoulder/elbow joints -->
  <!-- measured from model -->
  <!-- measured from model -->
  <!-- link lengths used in model -->

  <link name="base_link">
    <visual>
      <geometry>
        <mesh filename="package://ur_description/meshes/ur10/collision/base.stl"/>
      </geometry>
      <material name="LightGrey">
        <color rgba="0.7 0.7 0.7 1.0"/>
      </material>
    </visual>
    <collision>
      <geometry>
        <mesh filename="package://ur_description/meshes/ur10/collision/base.stl"/>
      </geometry>
    </collision>
    <inertial>
      <mass value="4.0"/>
      <origin rpy="0 0 0" xyz="0.0 0.0 0.0"/>
      <inertia ixx="0.0061063308908" ixy="0.0" ixz="0.0" iyy="0.0061063308908" iyz="0.0" izz="0.01125"/>
    </inertial>
  </link>
  <joint name="shoulder_pan_joint" type="revolute">
    <parent link="base_link"/>
    <child link="shoulder_link"/>
    <origin rpy="0.0 0.0 0.0" xyz="0.0 0.0 0.1273"/>
    <axis xyz="0 0 1"/>
    <limit effort="330.0" lower="-6.28318530718" upper="6.28318530718" velocity="2.16"/>
    <dynamics damping="0.0" friction="0.0"/>
  </joint>
  <link name="shoulder_link">
    <visual>
      <geometry>
        <mesh filename="package://ur_description/meshes/ur10/collision/shoulder.stl"/>
      </geometry>
      <material name="LightGrey">
        <color rgba="0.7 0.7 0.7 1.0"/>
      </material>
    </visual>
    <collision>
      <geometry>
        <mesh filename="package://ur_description/meshes/ur10/collision/shoulder.stl"/>
      </geometry>
    </collision>
    <inertial>
      <mass value="7.778"/>
      <origin rpy="0 0 0" xyz="0.0 0.0 0.0"/>
      <inertia ixx="0.0314743125769" ixy="0.0" ixz="0.0" iyy="0.0314743125769" iyz="0.0" izz="0.021875625"/>
    </inertial>
  </link>
  <joint name="shoulder_lift_joint" type="revolute">
    <parent link="shoulder_link"/>
    <child link="upper_arm_link"/>
    <origin rpy="0.0 1.57079632679 0.0" xyz="0.0 0.220941 0.0"/>
    <axis xyz="0 1 0"/>
    <limit effort="330.0" lower="-6.28318530718" upper="6.28318530718" velocity="2.16"/>
    <dynamics damping="0.0" friction="0.0"/>
  </joint>
  <link name="upper_arm_link">
    <visual>
      <geometry>
        <mesh filename="package://ur_description/meshes/ur10/collision/upperarm.stl"/>
      </geometry>
      <material name="LightGrey">
        <color rgba="0.7 0.7 0.7 1.0"/>
      </material>
    </visual>
    <collision>
      <geometry>
        <mesh filename="package://ur_description/meshes/ur10/collision/upperarm.stl"/>
      </geometry>
    </collision>
    <inertial>
      <mass value="12.93"/>
      <origin rpy="0 0 0" xyz="0.0 0.0 0.306"/>
      <inertia ixx="0.421753803798" ixy="0.0" ixz="0.0" iyy="0.421753803798" iyz="0.0" izz="0.036365625"/>
    </inertial>
  </link>
  <joint name="elbow_joint" type="revolute">
    <parent link="upper_arm_link"/>
    <child link="forearm_link"/>
    <origin rpy="0.0 0.0 0.0" xyz="0.0 -0.1719 0.612"/>
    <axis xyz="0 1 0"/>
    <limit effort="150.0" lower="-6.28318530718" upper="6.28318530718" velocity="3.15"/>
    <dynamics damping="0.0" friction="0.0"/>
  </joint>
  <link name="forearm_link">
    <visual>
      <geometry>
        <mesh filename="package://ur_description/meshes/ur10/collision/forearm.stl"/>
      </geometry>
      <material name="LightGrey">
        <color rgba="0.7 0.7 0.7 1.0"/>
      </material>
    </visual>
    <collision>
      <geometry>
        <mesh filename="package://ur_description/meshes/ur10/collision/forearm.stl"/>
      </geometry>
    </collision>
    <inertial>
      <mass value="3.87"/>
      <origin rpy="0 0 0" xyz="0.0 0.0 0.28615"/>
      <inertia ixx="0.111069694097" ixy="0.0" ixz="0.0" iyy="0.111069694097" iyz="0.0" izz="0.010884375"/>
    </inertial>
  </link>
  <joint name="wrist_1_joint" type="revolute">
    <parent link="forearm_link"/>
    <child link="wrist_1_link"/>
    <origin rpy="0.0 1.57079632679 0.0" xyz="0.0 0.0 0.5723"/>
    <axis xyz="0 1 0"/>
    <limit effort="54.0" lower="-6.28318530718" upper="6.28318530718" velocity="3.2"/>
    <dynamics damping="0.0" friction="0.0"/>
  </joint>
  <link name="wrist_1_link">
    <visual>
      <geometry>
        <mesh filename="package://ur_description/meshes/ur10/collision/wrist1.stl"/>
      </geometry>
      <material name="LightGrey">
        <color rgba="0.7 0.7 0.7 1.0"/>
      </material>
    </visual>
    <collision>
      <geometry>
        <mesh filename="package://ur_description/meshes/ur10/collision/wrist1.stl"/>
      </geometry>
    </collision>
    <inertial>
      <mass value="1.96"/>
      <origin rpy="0 0 0" xyz="0.0 0.0 0.0"/>
      <inertia ixx="0.0051082479567" ixy="0.0" ixz="0.0" iyy="0.0051082479567" iyz="0.0" izz="0.0055125"/>
    </inertial>
  </link>
  <joint name="wrist_2_joint" type="revolute">
    <parent link="wrist_1_link"/>
    <child link="wrist_2_link"/>
    <origin rpy="0.0 0.0 0.0" xyz="0.0 0.1149 0.0"/>
    <axis xyz="0 0 1"/>
    <limit effort="54.0" lower="-6.28318530718" upper="6.28318530718" velocity="3.2"/>
    <dynamics damping="0.0" friction="0.0"/>
  </joint>
  <link name="wrist_2_link">
    <visual>
      <geometry>
        <mesh filename="package://ur_description/meshes/ur10/collision/wrist2.stl"/>
      </geometry>
      <material name="LightGrey">
        <color rgba="0.7 0.7 0.7 1.0"/>
      </material>
    </visual>
    <collision>
      <geometry>
        <mesh filename="package://ur_description/meshes/ur10/collision/wrist2.stl"/>
      </geometry>
    </collision>
    <inertial>
      <mass value="1.96"/>
      <origin rpy="0 0 0" xyz="0.0 0.0 0.0"/>
      <inertia ixx="0.0051082479567" ixy="0.0" ixz="0.0" iyy="0.0051082479567" iyz="0.0" izz="0.0055125"/>
    </inertial>
  </link>
  <joint name="wrist_3_joint" type="revolute">
    <parent link="wrist_2_link"/>
    <child link="wrist_3_link"/>
    <origin rpy="0.0 0.0 0.0" xyz="0.0 0.0 0.1157"/>
    <axis xyz="0 1 0"/>
    <limit effort="54.0" lower="-6.28318530718" upper="6.28318530718" velocity="3.2"/>
    <dynamics damping="0.0" friction="0.0"/>
  </joint>
  <link name="wrist_3_link">
    <visual>
      <geometry>
        <mesh filename="package://ur_description/meshes/ur10/collision/wrist3.stl"/>
      </geometry>
      <material name="LightGrey">
        <color rgba="0.7 0.7 0.7 1.0"/>
      </material>
    </visual>
    <collision>
      <geometry>
        <mesh filename="package://ur_description/meshes/ur10/collision/wrist3.stl"/>
      </geometry>
    </collision>
    <inertial>
      <mass value="0.202"/>
      <origin rpy="0 0 0" xyz="0.0 0.0 0.0"/>
      <inertia ixx="0.000526462289415" ixy="0.0" ixz="0.0" iyy="0.000526462289415" iyz="0.0" izz="0.000568125"/>
    </inertial>
  </link>
  <joint name="ee_fixed_joint" type="fixed">
    <parent link="wrist_3_link"/>
    <child link="ee_link"/>
    <origin rpy="0.0 0.0 1.57079632679" xyz="0.0 0.0922 0.0"/>
  </joint>
  <link name="ee_link">
    <collision>
      <geometry>
        <box size="0.01 0.01 0.01"/>
      </geometry>
      <origin rpy="0 0 0" xyz="-0.01 0 0"/>
    </collision>
  </link>
  <transmission name="shoulder_pan_trans">
    <type>transmission_interface/SimpleTransmission</type>
    <joint name="shoulder_pan_joint">
      <hardwareInterface>PositionJointInterface</hardwareInterface>
    </joint>
    <actuator name="shoulder_pan_motor">
      <mechanicalReduction>1</mechanicalReduction>
    </actuator>
  </transmission>
  <transmission name="shoulder_lift_trans">
    <type>transmission_interface/SimpleTransmission</type>
    <joint name="shoulder_lift_joint">
      <hardwareInterface>PositionJointInterface</hardwareInterface>
    </joint>
    <actuator name="shoulder_lift_motor">
      <mechanicalReduction>1</mechanicalReduction>
    </actuator>
  </transmission>
  <transmission name="elbow_trans">
    <type>transmission_interface/SimpleTransmission</type>
    <joint name="elbow_joint">
      <hardwareInterface>PositionJointInterface</hardwareInterface>
    </joint>
    <actuator name="elbow_motor">
      <mechanicalReduction>1</mechanicalReduction>
    </actuator>
  </transmission>
  <transmission name="wrist_1_trans">
    <type>transmission_interface/SimpleTransmission</type>
    <joint name="wrist_1_joint">
      <hardwareInterface>PositionJointInterface</hardwareInterface>
    </joint>
    <actuator name="wrist_1_motor">
      <mechanicalReduction>1</mechanicalReduction>
    </actuator>
  </transmission>
  <transmission name="wrist_2_trans">
    <type>transmission_interface/SimpleTransmission</type>
    <joint name="wrist_2_joint">
      <hardwareInterface>PositionJointInterface</hardwareInterface>
    </joint>
    <actuator name="wrist_2_motor">
      <mechanicalReduction>1</mechanicalReduction>
    </actuator>
  </transmission>
  <transmission name="wrist_3_trans">
    <type>transmission_interface/SimpleTransmission</type>
    <joint name="wrist_3_joint">
      <hardwareInterface>PositionJointInterface</hardwareInterface>
    </joint>
    <actuator name="wrist_3_motor">
      <mechanicalReduction>1</mechanicalReduction>
    </actuator>
  </transmission>
  <!-- nothing to do here at the moment -->
  <!-- ROS base_link to UR 'Base' Coordinates transform -->
  <link name="base"/>
  <joint name="base_link-base_fixed_joint" type="fixed">
    <!-- NOTE: this rotation is only needed as long as base_link itself is
                 not corrected wrt the real robot (ie: rotated over 180
                 degrees)
      -->
    <origin rpy="0 0 -3.14159265359" xyz="0 0 0"/>
    <parent link="base_link"/>
    <child link="base"/>
  </joint>
  <!-- Frame coincident with all-zeros TCP on UR controller -->
  <link name="tool0"/>
  <joint name="wrist_3_link-tool0_fixed_joint" type="fixed">
    <origin rpy="-1.57079632679 0 0" xyz="0 0.0922 0"/>
    <parent link="wrist_3_link"/>
    <child link="tool0"/>
  </joint>
  <link name="H1_base_attach"/>
  <material name="Blue">
    <color rgba="0.0 0.0 0.8 1.0"/>
  </material>
  <material name="Green">
    <color rgba="0.0 0.8 0.0 1.0"/>
  </material>
  <material name="BiotacGreen">
    <color rgba="0.31 0.85 0.42 1.0"/>
  </material>
  <material name="Grey">
    <color rgba="0.2 0.2 0.2 1.0"/>
  </material>
  <material name="LightGrey">
    <color rgba="0.6 0.6 0.6 1.0"/>
  </material>
  <material name="Red">
    <color rgba="0.8 0.0 0.0 1.0"/>
  </material>
  <material name="White">
    <color rgba="1.0 1.0 1.0 1.0"/>
  </material>
  <gazebo>
    <plugin filename="libgazebo_ros_control.so" name="ros_control">
      <robotSimType>gazebo_ros_control/DefaultRobotHWSim</robotSimType>
    </plugin>
  </gazebo>
  <link name="H1_WR_wrist_base_link">
    <inertial>
      <origin rpy="0 0 0" xyz="0.00326865129997316 -4.64589898998213E-06 0.0112847129271115"/>
      <mass value="0.126266795472122"/>
      <inertia ixx="7.45469352483292E-05" ixy="6.02324465005139E-09" ixz="7.48046652661961E-07" iyy="0.000152711306761993" iyz="2.66777152755212E-09" izz="0.000201286651417327"/>
    </inertial>
    <visual>
      <origin rpy="0 0 0" xyz="0 0 0"/>
      <geometry>
        <mesh filename="package://fh_desc/meshes/wrist_base.dae"/>
      </geometry>
      <material name="light_grey">
        <color rgba="0.75 0.75 0.75 1.0"/>
      </material>
    </visual>
    <collision>
      <origin rpy="0 0 0" xyz="0 0 0"/>
      <geometry>
        <mesh filename="package://fh_desc/meshes/wrist_base.dae"/>
      </geometry>
      <material name="light_grey">
        <color rgba="0.75 0.75 0.75 1.0"/>
      </material>
    </collision>
  </link>
  <link name="H1_WR_wrist">
    <inertial>
      <origin rpy="0 0 0" xyz="0.00160957599422527 -0.000629300457080406 0.0174740198321096"/>
      <mass value="0.111982108931474"/>
      <inertia ixx="7.18014678375949E-05" ixy="-9.11325601281988E-07" ixz="-2.80734883420538E-06" iyy="0.000184429517814393" iyz="-2.43285388562761E-07" izz="0.000238392777579217"/>
    </inertial>
    <visual>
      <origin rpy="0 0 0" xyz="0 0 0"/>
      <geometry>
        <mesh filename="package://fh_desc/meshes/wrist.dae"/>
      </geometry>
      <material name="light_grey">
        <color rgba="0.75 0.75 0.75 1.0"/>
      </material>
    </visual>
    <collision>
      <origin rpy="0 0 0" xyz="0 0 0"/>
      <geometry>
        <mesh filename="package://fh_desc/meshes/wrist.dae"/>
      </geometry>
      <material name="light_grey">
        <color rgba="0.75 0.75 0.75 1.0"/>
      </material>
    </collision>
  </link>
  <joint name="H1_WRJ1" type="revolute">
    <origin rpy="0 0 0" xyz="0 0 0.032"/>
    <parent link="H1_WR_wrist_base_link"/>
    <child link="H1_WR_wrist"/>
    <axis xyz="-1 0 0"/>
    <limit effort="50" lower="-0.785" upper="0.785" velocity="0.1"/>
    <dynamics damping="0.0" friction="0.0"/>
  </joint>
  <link name="H1_WR_force_torque_sensor">
    <inertial>
      <origin rpy="0 0 0" xyz="-2.94070736140857E-06 6.43877814287904E-05 0.0247092180043537"/>
      <mass value="0.0975991645938483"/>
      <inertia ixx="6.20729230428078E-05" ixy="-1.64643097783638E-08" ixz="-3.24429596458139E-08" iyy="6.18050372756729E-05" iyz="1.29139184791137E-08" izz="8.23283621428637E-05"/>
    </inertial>
    <visual>
      <origin rpy="0 0 0" xyz="0 0 0"/>
      <geometry>
        <mesh filename="package://fh_desc/meshes/force_torque_sensor.dae"/>
      </geometry>
      <material name="light_grey">
        <color rgba="0.75 0.75 0.75 1.0"/>
      </material>
    </visual>
    <collision>
      <origin rpy="0 0 0" xyz="0 0 0"/>
      <geometry>
        <mesh filename="package://fh_desc/meshes/force_torque_sensor.dae"/>
      </geometry>
      <material name="light_grey">
        <color rgba="0.75 0.75 0.75 1.0"/>
      </material>
    </collision>
  </link>
  <link name="H1_WR_face_plate"/>
  <joint name="H1_WR_wrist_to_ft_sensor" type="fixed">
    <origin rpy="0 0 0" xyz="0 0 0.015"/>
    <parent link="H1_WR_wrist"/>
    <child link="H1_WR_force_torque_sensor"/>
  </joint>
  <joint name="H1_WR_wrist_base" type="fixed">
    <origin rpy="0 0 0" xyz="0 0 0"/>
    <parent link="H1_base_attach"/>
    <child link="H1_WR_wrist_base_link"/>
  </joint>
  <joint name="H1_WRft_sensor_to_faceplate" type="fixed">
    <origin rpy="0 0 0" xyz="0 0 0.0505"/>
    <parent link="H1_WR_force_torque_sensor"/>
    <child link="H1_WR_face_plate"/>
  </joint>
  <transmission name="H1_WRJ1_transmission">
    <type>transmission_interface/SimpleTransmission</type>
    <actuator name="H1_WRJ1">
      <mechanicalReduction>1</mechanicalReduction>
    </actuator>
    <joint name="H1_WRJ1">
      <hardwareInterface>EffortJointInterface</hardwareInterface>
    </joint>
  </transmission>
  <link name="H1_base_link">
    <inertial>
      <origin rpy="0 0 0" xyz="0.000167074827019974 0.017647639199748 0.0354392421665256"/>
      <mass value="0.802291302622713"/>
      <inertia ixx="0.00268740968940699" ixy="-2.63877052807301E-06" ixz="8.21876760057436E-06" iyy="0.00273884664780255" iyz="0.000454017867570455" izz="0.00145589837379105"/>
    </inertial>
    <visual>
      <origin rpy="0 0 0" xyz="0 0 0"/>
      <geometry>
        <mesh filename="package://fh_desc/meshes/palm_base.dae"/>
      </geometry>
      <material name="light_grey">
        <color rgba="0.75 0.75 0.75 1.0"/>
      </material>
    </visual>
    <collision>
      <origin rpy="0 0 0" xyz="0 0 0"/>
      <geometry>
        <mesh filename="package://fh_desc/meshes/palm_base.dae"/>
      </geometry>
      <material name="light_grey">
        <color rgba="0.75 0.75 0.75 1.0"/>
      </material>
    </collision>
  </link>
  <joint name="H1Base" type="fixed">
    <origin rpy="0 0 0" xyz="0 0 0"/>
    <parent link="H1_WR_face_plate"/>
    <child link="H1_wrist_attach"/>
  </joint>
  <link name="H1_insert_F1"/>
  <joint name="H1_dummy_joint_1" type="fixed">
    <origin rpy="0 0 0" xyz="0 0.045 0.002"/>
    <parent link="H1_base_link"/>
    <child link="H1_insert_F1"/>
  </joint>
  <link name="H1_insert_F2"/>
  <joint name="H1_dummy_joint_2" type="fixed">
    <origin rpy="0 0 3.14159265359" xyz="0.038971 -0.0225 0.002"/>
    <parent link="H1_base_link"/>
    <child link="H1_insert_F2"/>
  </joint>
  <link name="H1_insert_F3"/>
  <joint name="H1_dummy_joint_3" type="fixed">
    <origin rpy="0 0 3.14159265359" xyz="-0.038971 -0.0225 0.002"/>
    <parent link="H1_base_link"/>
    <child link="H1_insert_F3"/>
  </joint>
  <link name="H1_wrist_attach"/>
  <joint name="H1_base_link_wrist_attach" type="fixed">
    <origin rpy="0 0 0" xyz="0 0 -0.0005"/>
    <child link="H1_base_link"/>
    <parent link="H1_wrist_attach"/>
  </joint>
  <link name="H1_F1_base_link">
    <inertial>
      <origin rpy="0 0 0" xyz="-0.00016975101978813 0.00197421910589327 0.0561457825889687"/>
      <mass value="0.206184327436554"/>
      <inertia ixx="0.000196208681085273" ixy="7.25965267883658E-08" ixz="-1.42989296818671E-06" iyy="0.00022500240306659" iyz="-8.62726850629812E-06" izz="7.34501911009421E-05"/>
    </inertial>
    <visual>
      <origin rpy="0 0 0" xyz="0 0 0"/>
      <geometry>
        <mesh filename="package://fh_desc/meshes/base_link.dae"/>
      </geometry>
      <material name="light_grey">
        <color rgba="0.75 0.75 0.75 1.0"/>
      </material>
    </visual>
    <collision>
      <origin rpy="0 0 0" xyz="0 0 0"/>
      <geometry>
        <mesh filename="package://fh_desc/meshes/base_link.dae"/>
      </geometry>
      <material name="light_grey">
        <color rgba="0.75 0.75 0.75 1.0"/>
      </material>
    </collision>
  </link>
  <link name="H1_F1_link_1">
    <inertial>
      <origin rpy="0 0 0" xyz="-0.000237426002648366 -0.000311474464416824 0.02717870175844"/>
      <mass value="0.148439137620102"/>
      <inertia ixx="7.87590932011867E-05" ixy="-2.09812809718026E-08" ixz="-4.7018912298647E-07" iyy="9.21180950643254E-05" iyz="1.02291530412464E-06" izz="4.38404666397581E-05"/>
    </inertial>
    <visual>
      <origin rpy="0 0 0" xyz="0 0 0"/>
      <geometry>
        <mesh filename="package://fh_desc/meshes/prox.dae"/>
      </geometry>
      <material name="light_grey">
        <color rgba="0.75 0.75 0.75 1.0"/>
      </material>
    </visual>
    <collision>
      <origin rpy="0 0 0" xyz="0 0 0"/>
      <geometry>
        <mesh filename="package://fh_desc/meshes/prox.dae"/>
      </geometry>
      <material name="light_grey">
        <color rgba="0.75 0.75 0.75 1.0"/>
      </material>
    </collision>
  </link>
  <link name="H1_F1_link_2">
    <inertial>
      <origin rpy="0 0 0" xyz="0.000688458734451483 -0.00121669160147178 0.0179379664791534"/>
      <mass value="0.0468986964963515"/>
      <inertia ixx="1.66577929038936E-05" ixy="1.91370536767985E-09" ixz="-7.90963473136566E-07" iyy="1.65880289089031E-05" iyz="-2.10962265976158E-06" izz="5.79382496615135E-06"/>
    </inertial>
    <visual>
      <origin rpy="0 0 0" xyz="0 0 0"/>
      <geometry>
        <mesh filename="package://fh_desc/meshes/dist.dae"/>
      </geometry>
      <material name="light_grey">
        <color rgba="0.75 0.75 0.75 1.0"/>
      </material>
    </visual>
    <collision>
      <origin rpy="0 0 0" xyz="0 0 0"/>
      <geometry>
        <mesh filename="package://fh_desc/meshes/dist.dae"/>
      </geometry>
      <material name="light_grey">
        <color rgba="0.75 0.75 0.75 1.0"/>
      </material>
    </collision>
  </link>
  <joint name="H1_F1Base" type="fixed">
    <origin rpy="0 0 0" xyz="0 0 0"/>
    <parent link="H1_insert_F1"/>
    <child link="H1_F1_base_link"/>
  </joint>
  <joint name="H1_F1J1" type="revolute">
    <origin rpy="0 0 0" xyz="0 0 0.096"/>
    <parent link="H1_F1_base_link"/>
    <child link="H1_F1_link_1"/>
    <axis xyz="1 0 0"/>
    <limit effort="50" lower="-1.57079632679" upper="1.0472" velocity="1.0"/>
    <dynamics damping="0.0" friction="0.0"/>
  </joint>
  <joint name="H1_F1J2" type="revolute">
    <origin rpy="0 0 0" xyz="0 0 0.06"/>
    <axis xyz="1 0 0"/>
    <parent link="H1_F1_link_1"/>
    <child link="H1_F1_link_2"/>
    <limit effort="50" lower="-1.04716" upper="1.57075" velocity="1.0"/>
    <dynamics damping="0.0" friction="0.0"/>
  </joint>
  <transmission name="H1_F1J1_transmission">
    <type>transmission_interface/SimpleTransmission</type>
    <actuator name="H1_F1J1">
      <mechanicalReduction>1</mechanicalReduction>
    </actuator>
    <joint name="H1_F1J1">
      <hardwareInterface>EffortJointInterface</hardwareInterface>
    </joint>
  </transmission>
  <transmission name="H1_F1J2_transmission">
    <type>transmission_interface/SimpleTransmission</type>
    <actuator name="H1_F1J2">
      <mechanicalReduction>1</mechanicalReduction>
    </actuator>
    <joint name="H1_F1J2">
      <hardwareInterface>EffortJointInterface</hardwareInterface>
    </joint>
  </transmission>
  <!-- finger tip -->
  <link name="H1_F1_tip">
    <inertial>
      <origin rpy="0 0 0" xyz="-0.000925580990320645 -0.00495543398528436 0.0355865585792753"/>
      <mass value="0.00906322686585137"/>
      <inertia ixx="1.10049088227995E-06" ixy="-3.7290982171096E-09" ixz="-9.54389365908683E-09" iyy="1.36130530510584E-06" iyz="6.66133713720777E-08" izz="6.42259773618367E-07"/>
    </inertial>
    <visual>
      <origin rpy="0 0 0" xyz="0 0 0"/>
      <geometry>
        <mesh filename="package://fh_desc/meshes/omd-d18-tip.dae"/>
      </geometry>
      <material name="light_grey">
        <color rgba="0.75 0.75 0.75 1.0"/>
      </material>
    </visual>
    <collision>
      <origin rpy="0 0 0" xyz="0 0 0"/>
      <geometry>
        <mesh filename="package://fh_desc/meshes/omd-d18-tip.dae"/>
      </geometry>
      <material name="light_grey">
        <color rgba="0.75 0.75 0.75 1.0"/>
      </material>
    </collision>
  </link>
  <link name="H1_F1_optoforce"/>
  <joint name="H1_F1_tip_to_optoforce" type="fixed">
    <parent link="H1_F1_tip"/>
    <child link="H1_F1_optoforce"/>
    <origin rpy="-0.35 0 0" xyz="0 -0.006 0.046"/>
  </joint>
  <joint name="H1_F1_tip" type="fixed">
    <parent link="H1_F1_link_2"/>
    <child link="H1_F1_tip"/>
  </joint>
  <link name="H1_F2_base_link">
    <inertial>
      <origin rpy="0 0 0" xyz="-0.00016975101978813 0.00197421910589327 0.0561457825889687"/>
      <mass value="0.206184327436554"/>
      <inertia ixx="0.000196208681085273" ixy="7.25965267883658E-08" ixz="-1.42989296818671E-06" iyy="0.00022500240306659" iyz="-8.62726850629812E-06" izz="7.34501911009421E-05"/>
    </inertial>
    <visual>
      <origin rpy="0 0 0" xyz="0 0 0"/>
      <geometry>
        <mesh filename="package://fh_desc/meshes/base_link.dae"/>
      </geometry>
      <material name="light_grey">
        <color rgba="0.75 0.75 0.75 1.0"/>
      </material>
    </visual>
    <collision>
      <origin rpy="0 0 0" xyz="0 0 0"/>
      <geometry>
        <mesh filename="package://fh_desc/meshes/base_link.dae"/>
      </geometry>
      <material name="light_grey">
        <color rgba="0.75 0.75 0.75 1.0"/>
      </material>
    </collision>
  </link>
  <link name="H1_F2_link_1">
    <inertial>
      <origin rpy="0 0 0" xyz="-0.000237426002648366 -0.000311474464416824 0.02717870175844"/>
      <mass value="0.148439137620102"/>
      <inertia ixx="7.87590932011867E-05" ixy="-2.09812809718026E-08" ixz="-4.7018912298647E-07" iyy="9.21180950643254E-05" iyz="1.02291530412464E-06" izz="4.38404666397581E-05"/>
    </inertial>
    <visual>
      <origin rpy="0 0 0" xyz="0 0 0"/>
      <geometry>
        <mesh filename="package://fh_desc/meshes/prox.dae"/>
      </geometry>
      <material name="light_grey">
        <color rgba="0.75 0.75 0.75 1.0"/>
      </material>
    </visual>
    <collision>
      <origin rpy="0 0 0" xyz="0 0 0"/>
      <geometry>
        <mesh filename="package://fh_desc/meshes/prox.dae"/>
      </geometry>
      <material name="light_grey">
        <color rgba="0.75 0.75 0.75 1.0"/>
      </material>
    </collision>
  </link>
  <link name="H1_F2_link_2">
    <inertial>
      <origin rpy="0 0 0" xyz="0.000688458734451483 -0.00121669160147178 0.0179379664791534"/>
      <mass value="0.0468986964963515"/>
      <inertia ixx="1.66577929038936E-05" ixy="1.91370536767985E-09" ixz="-7.90963473136566E-07" iyy="1.65880289089031E-05" iyz="-2.10962265976158E-06" izz="5.79382496615135E-06"/>
    </inertial>
    <visual>
      <origin rpy="0 0 0" xyz="0 0 0"/>
      <geometry>
        <mesh filename="package://fh_desc/meshes/dist.dae"/>
      </geometry>
      <material name="light_grey">
        <color rgba="0.75 0.75 0.75 1.0"/>
      </material>
    </visual>
    <collision>
      <origin rpy="0 0 0" xyz="0 0 0"/>
      <geometry>
        <mesh filename="package://fh_desc/meshes/dist.dae"/>
      </geometry>
      <material name="light_grey">
        <color rgba="0.75 0.75 0.75 1.0"/>
      </material>
    </collision>
  </link>
  <joint name="H1_F2Base" type="fixed">
    <origin rpy="0 0 0" xyz="0 0 0"/>
    <parent link="H1_insert_F2"/>
    <child link="H1_F2_base_link"/>
  </joint>
  <joint name="H1_F2J1" type="revolute">
    <origin rpy="0 0 0" xyz="0 0 0.096"/>
    <parent link="H1_F2_base_link"/>
    <child link="H1_F2_link_1"/>
    <axis xyz="1 0 0"/>
    <limit effort="30" lower="-1.57079632679" upper="1.0472" velocity="1.0"/>
    <dynamics damping="0.0" friction="0.0"/>
  </joint>
  <joint name="H1_F2J2" type="revolute">
    <origin rpy="0 0 0" xyz="0 0 0.06"/>
    <axis xyz="1 0 0"/>
    <parent link="H1_F2_link_1"/>
    <child link="H1_F2_link_2"/>
    <limit effort="30" lower="-1.04716" upper="1.57075" velocity="1.0"/>
    <dynamics damping="0.0" friction="0.0"/>
  </joint>
  <transmission name="H1_F2J1_transmission">
    <type>transmission_interface/SimpleTransmission</type>
    <actuator name="H1_F2J1">
      <mechanicalReduction>1</mechanicalReduction>
    </actuator>
    <joint name="H1_F2J1">
      <hardwareInterface>EffortJointInterface</hardwareInterface>
    </joint>
  </transmission>
  <transmission name="H1_F2J2_transmission">
    <type>transmission_interface/SimpleTransmission</type>
    <actuator name="H1_F2J2">
      <mechanicalReduction>1</mechanicalReduction>
    </actuator>
    <joint name="H1_F2J2">
      <hardwareInterface>EffortJointInterface</hardwareInterface>
    </joint>
  </transmission>
  <!-- finger tip -->
  <link name="H1_F2_tip">
    <inertial>
      <origin rpy="0 0 0" xyz="-0.000925580990320645 -0.00495543398528436 0.0355865585792753"/>
      <mass value="0.00906322686585137"/>
      <inertia ixx="1.10049088227995E-06" ixy="-3.7290982171096E-09" ixz="-9.54389365908683E-09" iyy="1.36130530510584E-06" iyz="6.66133713720777E-08" izz="6.42259773618367E-07"/>
    </inertial>
    <visual>
      <origin rpy="0 0 0" xyz="0 0 0"/>
      <geometry>
        <mesh filename="package://fh_desc/meshes/omd-d18-tip.dae"/>
      </geometry>
      <material name="light_grey">
        <color rgba="0.75 0.75 0.75 1.0"/>
      </material>
    </visual>
    <collision>
      <origin rpy="0 0 0" xyz="0 0 0"/>
      <geometry>
        <mesh filename="package://fh_desc/meshes/omd-d18-tip.dae"/>
      </geometry>
      <material name="light_grey">
        <color rgba="0.75 0.75 0.75 1.0"/>
      </material>
    </collision>
  </link>
  <link name="H1_F2_optoforce"/>
  <joint name="H1_F2_tip_to_optoforce" type="fixed">
    <parent link="H1_F2_tip"/>
    <child link="H1_F2_optoforce"/>
    <origin rpy="-0.35 0 0" xyz="0 -0.006 0.046"/>
  </joint>
  <joint name="H1_F2_tip" type="fixed">
    <parent link="H1_F2_link_2"/>
    <child link="H1_F2_tip"/>
  </joint>
  <link name="H1_F3_base_link">
    <inertial>
      <origin rpy="0 0 0" xyz="-0.00016975101978813 0.00197421910589327 0.0561457825889687"/>
      <mass value="0.206184327436554"/>
      <inertia ixx="0.000196208681085273" ixy="7.25965267883658E-08" ixz="-1.42989296818671E-06" iyy="0.00022500240306659" iyz="-8.62726850629812E-06" izz="7.34501911009421E-05"/>
    </inertial>
    <visual>
      <origin rpy="0 0 0" xyz="0 0 0"/>
      <geometry>
        <mesh filename="package://fh_desc/meshes/base_link.dae"/>
      </geometry>
      <material name="light_grey">
        <color rgba="0.75 0.75 0.75 1.0"/>
      </material>
    </visual>
    <collision>
      <origin rpy="0 0 0" xyz="0 0 0"/>
      <geometry>
        <mesh filename="package://fh_desc/meshes/base_link.dae"/>
      </geometry>
      <material name="light_grey">
        <color rgba="0.75 0.75 0.75 1.0"/>
      </material>
    </collision>
  </link>
  <link name="H1_F3_link_1">
    <inertial>
      <origin rpy="0 0 0" xyz="-0.000237426002648366 -0.000311474464416824 0.02717870175844"/>
      <mass value="0.148439137620102"/>
      <inertia ixx="7.87590932011867E-05" ixy="-2.09812809718026E-08" ixz="-4.7018912298647E-07" iyy="9.21180950643254E-05" iyz="1.02291530412464E-06" izz="4.38404666397581E-05"/>
    </inertial>
    <visual>
      <origin rpy="0 0 0" xyz="0 0 0"/>
      <geometry>
        <mesh filename="package://fh_desc/meshes/prox.dae"/>
      </geometry>
      <material name="light_grey">
        <color rgba="0.75 0.75 0.75 1.0"/>
      </material>
    </visual>
    <collision>
      <origin rpy="0 0 0" xyz="0 0 0"/>
      <geometry>
        <mesh filename="package://fh_desc/meshes/prox.dae"/>
      </geometry>
      <material name="light_grey">
        <color rgba="0.75 0.75 0.75 1.0"/>
      </material>
    </collision>
  </link>
  <link name="H1_F3_link_2">
    <inertial>
      <origin rpy="0 0 0" xyz="0.000688458734451483 -0.00121669160147178 0.0179379664791534"/>
      <mass value="0.0468986964963515"/>
      <inertia ixx="1.66577929038936E-05" ixy="1.91370536767985E-09" ixz="-7.90963473136566E-07" iyy="1.65880289089031E-05" iyz="-2.10962265976158E-06" izz="5.79382496615135E-06"/>
    </inertial>
    <visual>
      <origin rpy="0 0 0" xyz="0 0 0"/>
      <geometry>
        <mesh filename="package://fh_desc/meshes/dist.dae"/>
      </geometry>
      <material name="light_grey">
        <color rgba="0.75 0.75 0.75 1.0"/>
      </material>
    </visual>
    <collision>
      <origin rpy="0 0 0" xyz="0 0 0"/>
      <geometry>
        <mesh filename="package://fh_desc/meshes/dist.dae"/>
      </geometry>
      <material name="light_grey">
        <color rgba="0.75 0.75 0.75 1.0"/>
      </material>
    </collision>
  </link>
  <joint name="H1_F3Base" type="fixed">
    <origin rpy="0 0 0" xyz="0 0 0"/>
    <parent link="H1_insert_F3"/>
    <child link="H1_F3_base_link"/>
  </joint>
  <joint name="H1_F3J1" type="revolute">
    <origin rpy="0 0 0" xyz="0 0 0.096"/>
    <parent link="H1_F3_base_link"/>
    <child link="H1_F3_link_1"/>
    <axis xyz="1 0 0"/>
    <limit effort="30" lower="-1.57079632679" upper="1.0472" velocity="1.0"/>
    <dynamics damping="0.0" friction="0.0"/>
  </joint>
  <joint name="H1_F3J2" type="revolute">
    <origin rpy="0 0 0" xyz="0 0 0.06"/>
    <axis xyz="1 0 0"/>
    <parent link="H1_F3_link_1"/>
    <child link="H1_F3_link_2"/>
    <limit effort="30" lower="-1.04716" upper="1.57075" velocity="1.0"/>
    <dynamics damping="0.0" friction="0.0"/>
  </joint>
  <transmission name="H1_F3J1_transmission">
    <type>transmission_interface/SimpleTransmission</type>
    <actuator name="H1_F3J1">
      <mechanicalReduction>1</mechanicalReduction>
    </actuator>
    <joint name="H1_F3J1">
      <hardwareInterface>EffortJointInterface</hardwareInterface>
    </joint>
  </transmission>
  <transmission name="H1_F3J2_transmission">
    <type>transmission_interface/SimpleTransmission</type>
    <actuator name="H1_F3J2">
      <mechanicalReduction>1</mechanicalReduction>
    </actuator>
    <joint name="H1_F3J2">
      <hardwareInterface>EffortJointInterface</hardwareInterface>
    </joint>
  </transmission>
  <!-- finger tip -->
  <link name="H1_F3_tip">
    <inertial>
      <origin rpy="0 0 0" xyz="-0.000925580990320645 -0.00495543398528436 0.0355865585792753"/>
      <mass value="0.00906322686585137"/>
      <inertia ixx="1.10049088227995E-06" ixy="-3.7290982171096E-09" ixz="-9.54389365908683E-09" iyy="1.36130530510584E-06" iyz="6.66133713720777E-08" izz="6.42259773618367E-07"/>
    </inertial>
    <visual>
      <origin rpy="0 0 0" xyz="0 0 0"/>
      <geometry>
        <mesh filename="package://fh_desc/meshes/omd-d18-tip.dae"/>
      </geometry>
      <material name="light_grey">
        <color rgba="0.75 0.75 0.75 1.0"/>
      </material>
    </visual>
    <collision>
      <origin rpy="0 0 0" xyz="0 0 0"/>
      <geometry>
        <mesh filename="package://fh_desc/meshes/omd-d18-tip.dae"/>
      </geometry>
      <material name="light_grey">
        <color rgba="0.75 0.75 0.75 1.0"/>
      </material>
    </collision>
  </link>
  <link name="H1_F3_optoforce"/>
  <joint name="H1_F3_tip_to_optoforce" type="fixed">
    <parent link="H1_F3_tip"/>
    <child link="H1_F3_optoforce"/>
    <origin rpy="-0.35 0 0" xyz="0 -0.006 0.046"/>
  </joint>
  <joint name="H1_F3_tip" type="fixed">
    <parent link="H1_F3_link_2"/>
    <child link="H1_F3_tip"/>
  </joint>
  <joint name="arm_to_hand" type="fixed">
    <parent link="ee_link"/>
    <child link="H1_base_attach"/>
    <origin rpy="1.57079632679 3.14159265359 1.57079632679" xyz="0.012 0.0 0.0"/>
  </joint>
</robot>
